Workbook

Sheet Load_Baplie_Out_Plus
A1: Bay | B1: Slot | C1: Container Id | D1: Size | E1: POL | F1: POD | G1: Weight | H1: Carrier | I1: Type | J1: Class | K1: Setting | L1: Height | M1: Full | N1: Delivery | O1: Opt Port | P1: Container | Q1: Vessel Origem | R1: Booking Number | S1: Type | T1: Weight | U1: Temp | V1: IMO | W1: Booking party | X1: POO | Y1: FPOD | Z1: Revenue
A2: 31 | B2: 310806 | C2: ANON0000000 | D2: 20 | E2: USNFK | F2: RULED | G2: 21466 | H2: ART | I2: 22G1 | L2: OOG | M2: Full | N2: RULED | P2: =C2 | Q2: {=IFERROR(INDEX(Load_Booking_Report!AC:AC, MATCH(TRUE, ISNUMBER(FIND(SUBSTITUTE(C2," ",""), Load_Booking_Report!AL:AL)), 0)), "Not Found")} | R2: {=IFERROR(INDEX(Load_Booking_Report!C:C, MATCH(TRUE, ISNUMBER(FIND(SUBSTITUTE(C2," ",""), Load_Booking_Report!AL:AL)), 0)), "Not Found")} | S2: {=IFERROR(INDEX(Load_Booking_Report!AG:AG, MATCH(TRUE, ISNUMBER(FIND(SUBSTITUTE(C2," ",""), Load_Booking_Report!AL:AL)), 0)), "Not Found")} | T2: =G2 | U2: {=IFERROR( IF( INDEX(Load_Booking_Report!AM:AM, MATCH(TRUE, ISNUMBER(FIND(SUBSTITUTE(C2," ",""), Load_Booking_Report!AL:AL)), 0) )=0, "", INDEX(Load_Booking_Report!AM:AM, MATCH(TRUE, ISNUMBER(FIND(SUBSTITUTE(C2," ",""), Load_Booking_Report!AL:AL)), 0) ) ), "" )} | V2: {=IFERROR( IF( INDEX(Load_Booking_Report!AR:AR, MATCH(TRUE, ISNUMBER(FIND(SUBSTITUTE(C2," ",""), Load_Booking_Report!AL:AL)), 0) )=0, "", INDEX(Load_Booking_Report!AR:AR, MATCH(TRUE, ISNUMBER(FIND(SUBSTITUTE(C2," ",""), Load_Booking_Report!AL:AL)), 0) ) ), "" )} | W2: {=IFERROR(INDEX(Load_Booking_Report!F:F, MATCH(TRUE, ISNUMBER(FIND(SUBSTITUTE(C2," ",""), Load_Booking_Report!AL:AL)), 0)), "Not Found")} | X2: {=IFERROR(INDEX(Load_Booking_Report!N:N, MATCH(TRUE, ISNUMBER(FIND(SUBSTITUTE(C2," ",""), Load_Booking_Report!AL:AL)), 0)), "Not Found")} | Y2: {=IFERROR(INDEX(Load_Booking_Report!V:V, MATCH(TRUE, ISNUMBER(FIND(SUBSTITUTE(C2," ",""), Load_Booking_Report!AL:AL)), 0)), "Not Found")} | Z2: {=IFERROR(INDEX(Load_Booking_Report!BC:BC, MATCH(TRUE, ISNUMBER(FIND(SUBSTITUTE(C2," ",""), Load_Booking_Report!AL:AL)), 0)), "Not Found")}
A3: 25 | B3: 250504 | C3: ANON0000000 | D3: 20 | E3: USNYC | F3: RULED | G3: 27050 | H3: ART | I3: 22G1 | L3: 8'6 | M3: Full | N3: RULED | P3: =C3 | Q3: {=IFERROR(INDEX(Load_Booking_Report!AC:AC, MATCH(TRUE, ISNUMBER(FIND(SUBSTITUTE(C3," ",""), Load_Booking_Report!AL:AL)), 0)), "Not Found")} | R3: {=IFERROR(INDEX(Load_Booking_Report!C:C, MATCH(TRUE, ISNUMBER(FIND(SUBSTITUTE(C3," ",""), Load_Booking_Report!AL:AL)), 0)), "Not Found")} | S3: {=IFERROR(INDEX(Load_Booking_Report!AG:AG, MATCH(TRUE, ISNUMBER(FIND(SUBSTITUTE(C3," ",""), Load_Booking_Report!AL:AL)), 0)), "Not Found")} | T3: =G3 | U3: {=IFERROR( IF( INDEX(Load_Booking_Report!AM:AM, MATCH(TRUE, ISNUMBER(FIND(SUBSTITUTE(C3," ",""), Load_Booking_Report!AL:AL)), 0) )=0, "", INDEX(Load_Booking_Report!AM:AM, MATCH(TRUE, ISNUMBER(FIND(SUBSTITUTE(C3," ",""), Load_Booking_Report!AL:AL)), 0) ) ), "" )} | V3: {=IFERROR( IF( INDEX(Load_Booking_Report!AR:AR, MATCH(TRUE, ISNUMBER(FIND(SUBSTITUTE(C3," ",""), Load_Booking_Report!AL:AL)), 0) )=0, "", INDEX(Load_Booking_Report!AR:AR, MATCH(TRUE, ISNUMBER(FIND(SUBSTITUTE(C3," ",""), Load_Booking_Report!AL:AL)), 0) ) ), "" )} | W3: {=IFERROR(INDEX(Load_Booking_Report!F:F, MATCH(TRUE, ISNUMBER(FIND(SUBSTITUTE(C3," ",""), Load_Booking_Report!AL:AL)), 0)), "Not Found")} | X3: {=IFERROR(INDEX(Load_Booking_Report!N:N, MATCH(TRUE, ISNUMBER(FIND(SUBSTITUTE(C3," ",""), Load_Booking_Report!AL:AL)), 0)), "Not Found")} | Y3: {=IFERROR(INDEX(Load_Booking_Report!V:V, MATCH(TRUE, ISNUMBER(FIND(SUBSTITUTE(C3," ",""), Load_Booking_Report!AL:AL)), 0)), "Not Found")} | Z3: {=IFERROR(INDEX(Load_Booking_Report!BC:BC, MATCH(TRUE, ISNUMBER(FIND(SUBSTITUTE(C3," ",""), Load_Booking_Report!AL:AL)), 0)), "Not Found")}
A4: 27 | B4: 270302 | C4: ANON0000000 | D4: 20 | E4: USNYC | F4: RULED | G4: 27000 | H4: ART | I4: 22G1 | L4: 8'6 | M4: Full | N4: RULED | P4: =C4 | Q4: {=IFERROR(INDEX(Load_Booking_Report!AC:AC, MATCH(TRUE, ISNUMBER(FIND(SUBSTITUTE(C4," ",""), Load_Booking_Report!AL:AL)), 0)), "Not Found")} | R4: {=IFERROR(INDEX(Load_Booking_Report!C:C, MATCH(TRUE, ISNUMBER(FIND(SUBSTITUTE(C4," ",""), Load_Booking_Report!AL:AL)), 0)), "Not Found")} | S4: {=IFERROR(INDEX(Load_Booking_Report!AG:AG, MATCH(TRUE, ISNUMBER(FIND(SUBSTITUTE(C4," ",""), Load_Booking_Report!AL:AL)), 0)), "Not Found")} | T4: =G4 | U4: {=IFERROR( IF( INDEX(Load_Booking_Report!AM:AM, MATCH(TRUE, ISNUMBER(FIND(SUBSTITUTE(C4," ",""), Load_Booking_Report!AL:AL)), 0) )=0, "", INDEX(Load_Booking_Report!AM:AM, MATCH(TRUE, ISNUMBER(FIND(SUBSTITUTE(C4," ",""), Load_Booking_Report!AL:AL)), 0) ) ), "" )} | V4: {=IFERROR( IF( INDEX(Load_Booking_Report!AR:AR, MATCH(TRUE, ISNUMBER(FIND(SUBSTITUTE(C4," ",""), Load_Booking_Report!AL:AL)), 0) )=0, "", INDEX(Load_Booking_Report!AR:AR, MATCH(TRUE, ISNUMBER(FIND(SUBSTITUTE(C4," ",""), Load_Booking_Report!AL:AL)), 0) ) ), "" )} | W4: {=IFERROR(INDEX(Load_Booking_Report!F:F, MATCH(TRUE, ISNUMBER(FIND(SUBSTITUTE(C4," ",""), Load_Booking_Report!AL:AL)), 0)), "Not Found")} | X4: {=IFERROR(INDEX(Load_Booking_Report!N:N, MATCH(TRUE, ISNUMBER(FIND(SUBSTITUTE(C4," ",""), Load_Booking_Report!AL:AL)), 0)), "Not Found")} | Y4: {=IFERROR(INDEX(Load_Booking_Report!V:V, MATCH(TRUE, ISNUMBER(FIND(SUBSTITUTE(C4," ",""), Load_Booking_Report!AL:AL)), 0)), "Not Found")} | Z4: {=IFERROR(INDEX(Load_Booking_Report!BC:BC, MATCH(TRUE, ISNUMBER(FIND(SUBSTITUTE(C4," ",""), Load_Booking_Report!AL:AL)), 0)), "Not Found")}
A5: 25 | B5: 250302 | C5: ANON0000000 | D5: 20 | E5: USNYC | F5: RULED | G5: 27040 | H5: ART | I5: 22G1 | L5: 8'6 | M5: Full | N5: RULED | P5: =C5 | Q5: {=IFERROR(INDEX(Load_Booking_Report!AC:AC, MATCH(TRUE, ISNUMBER(FIND(SUBSTITUTE(C5," ",""), Load_Booking_Report!AL:AL)), 0)), "Not Found")} | R5: {=IFERROR(INDEX(Load_Booking_Report!C:C, MATCH(TRUE, ISNUMBER(FIND(SUBSTITUTE(C5," ",""), Load_Booking_Report!AL:AL)), 0)), "Not Found")} | S5: {=IFERROR(INDEX(Load_Booking_Report!AG:AG, MATCH(TRUE, ISNUMBER(FIND(SUBSTITUTE(C5," ",""), Load_Booking_Report!AL:AL)), 0)), "Not Found")} | T5: =G5 | U5: {=IFERROR( IF( INDEX(Load_Booking_Report!AM:AM, MATCH(TRUE, ISNUMBER(FIND(SUBSTITUTE(C5," ",""), Load_Booking_Report!AL:AL)), 0) )=0, "", INDEX(Load_Booking_Report!AM:AM, MATCH(TRUE, ISNUMBER(FIND(SUBSTITUTE(C5," ",""), Load_Booking_Report!AL:AL)), 0) ) ), "" )} | V5: {=IFERROR( IF( INDEX(Load_Booking_Report!AR:AR, MATCH(TRUE, ISNUMBER(FIND(SUBSTITUTE(C5," ",""), Load_Booking_Report!AL:AL)), 0) )=0, "", INDEX(Load_Booking_Report!AR:AR, MATCH(TRUE, ISNUMBER(FIND(SUBSTITUTE(C5," ",""), Load_Booking_Report!AL:AL)), 0) ) ), "" )} | W5: {=IFERROR(INDEX(Load_Booking_Report!F:F, MATCH(TRUE, ISNUMBER(FIND(SUBSTITUTE(C5," ",""), Load_Booking_Report!AL:AL)), 0)), "Not Found")} | X5: {=IFERROR(INDEX(Load_Booking_Report!N:N, MATCH(TRUE, ISNUMBER(FIND(SUBSTITUTE(C5," ",""), Load_Booking_Report!AL:AL)), 0)), "Not Found")} | Y5: {=IFERROR(INDEX(Load_Booking_Report!V:V, MATCH(TRUE, ISNUMBER(FIND(SUBSTITUTE(C5," ",""), Load_Booking_Report!AL:AL)), 0)), "Not Found")} | Z5: {=IFERROR(INDEX(Load_Booking_Report!BC:BC, MATCH(TRUE, ISNUMBER(FIND(SUBSTITUTE(C5," ",""), Load_Booking_Report!AL:AL)), 0)), "Not Found")}
A6: 33 | B6: 330604 | C6: ANON0000000 | D6: 20 | E6: USNYC | F6: RULED | G6: 26900 | H6: ART | I6: 22G1 | L6: 8'6 | M6: Full | N6: RULED | P6: =C6 | Q6: {=IFERROR(INDEX(Load_Booking_Report!AC:AC, MATCH(TRUE, ISNUMBER(FIND(SUBSTITUTE(C6," ",""), Load_Booking_Report!AL:AL)), 0)), "Not Found")} | R6: {=IFERROR(INDEX(Load_Booking_Report!C:C, MATCH(TRUE, ISNUMBER(FIND(SUBSTITUTE(C6," ",""), Load_Booking_Report!AL:AL)), 0)), "Not Found")} | S6: {=IFERROR(INDEX(Load_Booking_Report!AG:AG, MATCH(TRUE, ISNUMBER(FIND(SUBSTITUTE(C6," ",""), Load_Booking_Report!AL:AL)), 0)), "Not Found")} | T6: =G6 | U6: {=IFERROR( IF( INDEX(Load_Booking_Report!AM:AM, MATCH(TRUE, ISNUMBER(FIND(SUBSTITUTE(C6," ",""), Load_Booking_Report!AL:AL)), 0) )=0, "", INDEX(Load_Booking_Report!AM:AM, MATCH(TRUE, ISNUMBER(FIND(SUBSTITUTE(C6," ",""), Load_Booking_Report!AL:AL)), 0) ) ), "" )} | V6: {=IFERROR( IF( INDEX(Load_Booking_Report!AR:AR, MATCH(TRUE, ISNUMBER(FIND(SUBSTITUTE(C6," ",""), Load_Booking_Report!AL:AL)), 0) )=0, "", INDEX(Load_Booking_Report!AR:AR, MATCH(TRUE, ISNUMBER(FIND(SUBSTITUTE(C6," ",""), Load_Booking_Report!AL:AL)), 0) ) ), "" )} | W6: {=IFERROR(INDEX(Load_Booking_Report!F:F, MATCH(TRUE, ISNUMBER(FIND(SUBSTITUTE(C6," ",""), Load_Booking_Report!AL:AL)), 0)), "Not Found")} | X6: {=IFERROR(INDEX(Load_Booking_Report!N:N, MATCH(TRUE, ISNUMBER(FIND(SUBSTITUTE(C6," ",""), Load_Booking_Report!AL:AL)), 0)), "Not Found")} | Y6: {=IFERROR(INDEX(Load_Booking_Report!V:V, MATCH(TRUE, ISNUMBER(FIND(SUBSTITUTE(C6," ",""), Load_Booking_Report!AL:AL)), 0)), "Not Found")} | Z6: {=IFERROR(INDEX(Load_Booking_Report!BC:BC, MATCH(TRUE, ISNUMBER(FIND(SUBSTITUTE(C6," ",""), Load_Booking_Report!AL:AL)), 0)), "Not Found")}
A7: 27 | B7: 270206 | C7: ANON0000000 | D7: 20 | E7: USNYC | F7: RULED | G7: 27110 | H7: ART | I7: 22G1 | L7: 8'6 | M7: Full | N7: RULED | P7: =C7 | Q7: {=IFERROR(INDEX(Load_Booking_Report!AC:AC, MATCH(TRUE, ISNUMBER(FIND(SUBSTITUTE(C7," ",""), Load_Booking_Report!AL:AL)), 0)), "Not Found")} | R7: {=IFERROR(INDEX(Load_Booking_Report!C:C, MATCH(TRUE, ISNUMBER(FIND(SUBSTITUTE(C7," ",""), Load_Booking_Report!AL:AL)), 0)), "Not Found")} | S7: {=IFERROR(INDEX(Load_Booking_Report!AG:AG, MATCH(TRUE, ISNUMBER(FIND(SUBSTITUTE(C7," ",""), Load_Booking_Report!AL:AL)), 0)), "Not Found")} | T7: =G7 | U7: {=IFERROR( IF( INDEX(Load_Booking_Report!AM:AM, MATCH(TRUE, ISNUMBER(FIND(SUBSTITUTE(C7," ",""), Load_Booking_Report!AL:AL)), 0) )=0, "", INDEX(Load_Booking_Report!AM:AM, MATCH(TRUE, ISNUMBER(FIND(SUBSTITUTE(C7," ",""), Load_Booking_Report!AL:AL)), 0) ) ), "" )} | V7: {=IFERROR( IF( INDEX(Load_Booking_Report!AR:AR, MATCH(TRUE, ISNUMBER(FIND(SUBSTITUTE(C7," ",""), Load_Booking_Report!AL:AL)), 0) )=0, "", INDEX(Load_Booking_Report!AR:AR, MATCH(TRUE, ISNUMBER(FIND(SUBSTITUTE(C7," ",""), Load_Booking_Report!AL:AL)), 0) ) ), "" )} | W7: {=IFERROR(INDEX(Load_Booking_Report!F:F, MATCH(TRUE, ISNUMBER(FIND(SUBSTITUTE(C7," ",""), Load_Booking_Report!AL:AL)), 0)), "Not Found")} | X7: {=IFERROR(INDEX(Load_Booking_Report!N:N, MATCH(TRUE, ISNUMBER(FIND(SUBSTITUTE(C7," ",""), Load_Booking_Report!AL:AL)), 0)), "Not Found")} | Y7: {=IFERROR(INDEX(Load_Booking_Report!V:V, MATCH(TRUE, ISNUMBER(FIND(SUBSTITUTE(C7," ",""), Load_Booking_Report!AL:AL)), 0)), "Not Found")} | Z7: {=IFERROR(INDEX(Load_Booking_Report!BC:BC, MATCH(TRUE, ISNUMBER(FIND(SUBSTITUTE(C7," ",""), Load_Booking_Report!AL:AL)), 0)), "Not Found")}
A8: 9 | B8: 90102 | C8: ANON0000000 | D8: 20 | E8: USNFK | F8: RULED | G8: 21448 | H8: ART | I8: 22G1 | L8: OOG | M8: Full | N8: RULED | P8: =C8 | Q8: {=IFERROR(INDEX(Load_Booking_Report!AC:AC, MATCH(TRUE, ISNUMBER(FIND(SUBSTITUTE(C8," ",""), Load_Booking_Report!AL:AL)), 0)), "Not Found")} | R8: {=IFERROR(INDEX(Load_Booking_Report!C:C, MATCH(TRUE, ISNUMBER(FIND(SUBSTITUTE(C8," ",""), Load_Booking_Report!AL:AL)), 0)), "Not Found")} | S8: {=IFERROR(INDEX(Load_Booking_Report!AG:AG, MATCH(TRUE, ISNUMBER(FIND(SUBSTITUTE(C8," ",""), Load_Booking_Report!AL:AL)), 0)), "Not Found")} | T8: =G8 | U8: {=IFERROR( IF( INDEX(Load_Booking_Report!AM:AM, MATCH(TRUE, ISNUMBER(FIND(SUBSTITUTE(C8," ",""), Load_Booking_Report!AL:AL)), 0) )=0, "", INDEX(Load_Booking_Report!AM:AM, MATCH(TRUE, ISNUMBER(FIND(SUBSTITUTE(C8," ",""), Load_Booking_Report!AL:AL)), 0) ) ), "" )} | V8: {=IFERROR( IF( INDEX(Load_Booking_Report!AR:AR, MATCH(TRUE, ISNUMBER(FIND(SUBSTITUTE(C8," ",""), Load_Booking_Report!AL:AL)), 0) )=0, "", INDEX(Load_Booking_Report!AR:AR, MATCH(TRUE, ISNUMBER(FIND(SUBSTITUTE(C8," ",""), Load_Booking_Report!AL:AL)), 0) ) ), "" )} | W8: {=IFERROR(INDEX(Load_Booking_Report!F:F, MATCH(TRUE, ISNUMBER(FIND(SUBSTITUTE(C8," ",""), Load_Booking_Report!AL:AL)), 0)), "Not Found")} | X8: {=IFERROR(INDEX(Load_Booking_Report!N:N, MATCH(TRUE, ISNUMBER(FIND(SUBSTITUTE(C8," ",""), Load_Booking_Report!AL:AL)), 0)), "Not Found")} | Y8: {=IFERROR(INDEX(Load_Booking_Report!V:V, MATCH(TRUE, ISNUMBER(FIND(SUBSTITUTE(C8," ",""), Load_Booking_Report!AL:AL)), 0)), "Not Found")} | Z8: {=IFERROR(INDEX(Load_Booking_Report!BC:BC, MATCH(TRUE, ISNUMBER(FIND(SUBSTITUTE(C8," ",""), Load_Booking_Report!AL:AL)), 0)), "Not Found")}
A9: 27 | B9: 270108 | C9: ANON0000000 | D9: 20 | E9: USNYC | F9: RULED | G9: 27100 | H9: ART | I9: 22G1 | L9: 8'6 | M9: Full | N9: RUBLT | P9: =C9 | Q9: {=IFERROR(INDEX(Load_Booking_Report!AC:AC, MATCH(TRUE, ISNUMBER(FIND(SUBSTITUTE(C9," ",""), Load_Booking_Report!AL:AL)), 0)), "Not Found")} | R9: {=IFERROR(INDEX(Load_Booking_Report!C:C, MATCH(TRUE, ISNUMBER(FIND(SUBSTITUTE(C9," ",""), Load_Booking_Report!AL:AL)), 0)), "Not Found")} | S9: {=IFERROR(INDEX(Load_Booking_Report!AG:AG, MATCH(TRUE, ISNUMBER(FIND(SUBSTITUTE(C9," ",""), Load_Booking_Report!AL:AL)), 0)), "Not Found")} | T9: =G9 | U9: {=IFERROR( IF( INDEX(Load_Booking_Report!AM:AM, MATCH(TRUE, ISNUMBER(FIND(SUBSTITUTE(C9," ",""), Load_Booking_Report!AL:AL)), 0) )=0, "", INDEX(Load_Booking_Report!AM:AM, MATCH(TRUE, ISNUMBER(FIND(SUBSTITUTE(C9," ",""), Load_Booking_Report!AL:AL)), 0) ) ), "" )} | V9: {=IFERROR( IF( INDEX(Load_Booking_Report!AR:AR, MATCH(TRUE, ISNUMBER(FIND(SUBSTITUTE(C9," ",""), Load_Booking_Report!AL:AL)), 0) )=0, "", INDEX(Load_Booking_Report!AR:AR, MATCH(TRUE, ISNUMBER(FIND(SUBSTITUTE(C9," ",""), Load_Booking_Report!AL:AL)), 0) ) ), "" )} | W9: {=IFERROR(INDEX(Load_Booking_Report!F:F, MATCH(TRUE, ISNUMBER(FIND(SUBSTITUTE(C9," ",""), Load_Booking_Report!AL:AL)), 0)), "Not Found")} | X9: {=IFERROR(INDEX(Load_Booking_Report!N:N, MATCH(TRUE, ISNUMBER(FIND(SUBSTITUTE(C9," ",""), Load_Booking_Report!AL:AL)), 0)), "Not Found")} | Y9: {=IFERROR(INDEX(Load_Booking_Report!V:V, MATCH(TRUE, ISNUMBER(FIND(SUBSTITUTE(C9," ",""), Load_Booking_Report!AL:AL)), 0)), "Not Found")} | Z9: {=IFERROR(INDEX(Load_Booking_Report!BC:BC, MATCH(TRUE, ISNUMBER(FIND(SUBSTITUTE(C9," ",""), Load_Booking_Report!AL:AL)), 0)), "Not Found")}
A10: 25 | B10: 250108 | C10: ANON0000000 | D10: 20 | E10: USNYC | F10: RULED | G10: 27100 | H10: ART | I10: 22G1 | L10: 8'6 | M10: Full | N10: RULED | P10: =C10 | Q10: {=IFERROR(INDEX(Load_Booking_Report!AC:AC, MATCH(TRUE, ISNUMBER(FIND(SUBSTITUTE(C10," ",""), Load_Booking_Report!AL:AL)), 0)), "Not Found")} | R10: {=IFERROR(INDEX(Load_Booking_Report!C:C, MATCH(TRUE, ISNUMBER(FIND(SUBSTITUTE(C10," ",""), Load_Booking_Report!AL:AL)), 0)), "Not Found")} | S10: {=IFERROR(INDEX(Load_Booking_Report!AG:AG, MATCH(TRUE, ISNUMBER(FIND(SUBSTITUTE(C10," ",""), Load_Booking_Report!AL:AL)), 0)), "Not Found")} | T10: =G10 | U10: {=IFERROR( IF( INDEX(Load_Booking_Report!AM:AM, MATCH(TRUE, ISNUMBER(FIND(SUBSTITUTE(C10," ",""), Load_Booking_Report!AL:AL)), 0) )=0, "", INDEX(Load_Booking_Report!AM:AM, MATCH(TRUE, ISNUMBER(FIND(SUBSTITUTE(C10," ",""), Load_Booking_Report!AL:AL)), 0) ) ), "" )} | V10: {=IFERROR( IF( INDEX(Load_Booking_Report!AR:AR, MATCH(TRUE, ISNUMBER(FIND(SUBSTITUTE(C10," ",""), Load_Booking_Report!AL:AL)), 0) )=0, "", INDEX(Load_Booking_Report!AR:AR, MATCH(TRUE, ISNUMBER(FIND(SUBSTITUTE(C10," ",""), Load_Booking_Report!AL:AL)), 0) ) ), "" )} | W10: {=IFERROR(INDEX(Load_Booking_Report!F:F, MATCH(TRUE, ISNUMBER(FIND(SUBSTITUTE(C10," ",""), Load_Booking_Report!AL:AL)), 0)), "Not Found")} | X10: {=IFERROR(INDEX(Load_Booking_Report!N:N, MATCH(TRUE, ISNUMBER(FIND(SUBSTITUTE(C10," ",""), Load_Booking_Report!AL:AL)), 0)), "Not Found")} | Y10: {=IFERROR(INDEX(Load_Booking_Report!V:V, MATCH(TRUE, ISNUMBER(FIND(SUBSTITUTE(C10," ",""), Load_Booking_Report!AL:AL)), 0)), "Not Found")} | Z10: {=IFERROR(INDEX(Load_Booking_Report!BC:BC, MATCH(TRUE, ISNUMBER(FIND(SUBSTITUTE(C10," ",""), Load_Booking_Report!AL:AL)), 0)), "Not Found")}
A11: 25 | B11: 250106 | C11: ANON0000000 | D11: 20 | E11: USNYC | F11: RULED | G11: 26980 | H11: ART | I11: 22G1 | L11: 8'6 | M11: Full | N11: RULED | P11: =C11 | Q11: {=IFERROR(INDEX(Load_Booking_Report!AC:AC, MATCH(TRUE, ISNUMBER(FIND(SUBSTITUTE(C11," ",""), Load_Booking_Report!AL:AL)), 0)), "Not Found")} | R11: {=IFERROR(INDEX(Load_Booking_Report!C:C, MATCH(TRUE, ISNUMBER(FIND(SUBSTITUTE(C11," ",""), Load_Booking_Report!AL:AL)), 0)), "Not Found")} | S11: {=IFERROR(INDEX(Load_Booking_Report!AG:AG, MATCH(TRUE, ISNUMBER(FIND(SUBSTITUTE(C11," ",""), Load_Booking_Report!AL:AL)), 0)), "Not Found")} | T11: =G11 | U11: {=IFERROR( IF( INDEX(Load_Booking_Report!AM:AM, MATCH(TRUE, ISNUMBER(FIND(SUBSTITUTE(C11," ",""), Load_Booking_Report!AL:AL)), 0) )=0, "", INDEX(Load_Booking_Report!AM:AM, MATCH(TRUE, ISNUMBER(FIND(SUBSTITUTE(C11," ",""), Load_Booking_Report!AL:AL)), 0) ) ), "" )} | V11: {=IFERROR( IF( INDEX(Load_Booking_Report!AR:AR, MATCH(TRUE, ISNUMBER(FIND(SUBSTITUTE(C11," ",""), Load_Booking_Report!AL:AL)), 0) )=0, "", INDEX(Load_Booking_Report!AR:AR, MATCH(TRUE, ISNUMBER(FIND(SUBSTITUTE(C11," ",""), Load_Booking_Report!AL:AL)), 0) ) ), "" )} | W11: {=IFERROR(INDEX(Load_Booking_Report!F:F, MATCH(TRUE, ISNUMBER(FIND(SUBSTITUTE(C11," ",""), Load_Booking_Report!AL:AL)), 0)), "Not Found")} | X11: {=IFERROR(INDEX(Load_Booking_Report!N:N, MATCH(TRUE, ISNUMBER(FIND(SUBSTITUTE(C11," ",""), Load_Booking_Report!AL:AL)), 0)), "Not Found")} | Y11: {=IFERROR(INDEX(Load_Booking_Report!V:V, MATCH(TRUE, ISNUMBER(FIND(SUBSTITUTE(C11," ",""), Load_Booking_Report!AL:AL)), 0)), "Not Found")} | Z11: {=IFERROR(INDEX(Load_Booking_Report!BC:BC, MATCH(TRUE, ISNUMBER(FIND(SUBSTITUTE(C11," ",""), Load_Booking_Report!AL:AL)), 0)), "Not Found")}
A12: 7 | B12: 70508 | C12: ANON0000000 | D12: 20 | E12: USNFK | F12: RULED | G12: 28300 | H12: ART | I12: 22G1 | L12: 8'6 | M12: Full | N12: RULED | P12: =C12 | Q12: {=IFERROR(INDEX(Load_Booking_Report!AC:AC, MATCH(TRUE, ISNUMBER(FIND(SUBSTITUTE(C12," ",""), Load_Booking_Report!AL:AL)), 0)), "Not Found")} | R12: {=IFERROR(INDEX(Load_Booking_Report!C:C, MATCH(TRUE, ISNUMBER(FIND(SUBSTITUTE(C12," ",""), Load_Booking_Report!AL:AL)), 0)), "Not Found")} | S12: {=IFERROR(INDEX(Load_Booking_Report!AG:AG, MATCH(TRUE, ISNUMBER(FIND(SUBSTITUTE(C12," ",""), Load_Booking_Report!AL:AL)), 0)), "Not Found")} | T12: =G12 | U12: {=IFERROR( IF( INDEX(Load_Booking_Report!AM:AM, MATCH(TRUE, ISNUMBER(FIND(SUBSTITUTE(C12," ",""), Load_Booking_Report!AL:AL)), 0) )=0, "", INDEX(Load_Booking_Report!AM:AM, MATCH(TRUE, ISNUMBER(FIND(SUBSTITUTE(C12," ",""), Load_Booking_Report!AL:AL)), 0) ) ), "" )} | V12: {=IFERROR( IF( INDEX(Load_Booking_Report!AR:AR, MATCH(TRUE, ISNUMBER(FIND(SUBSTITUTE(C12," ",""), Load_Booking_Report!AL:AL)), 0) )=0, "", INDEX(Load_Booking_Report!AR:AR, MATCH(TRUE, ISNUMBER(FIND(SUBSTITUTE(C12," ",""), Load_Booking_Report!AL:AL)), 0) ) ), "" )} | W12: {=IFERROR(INDEX(Load_Booking_Report!F:F, MATCH(TRUE, ISNUMBER(FIND(SUBSTITUTE(C12," ",""), Load_Booking_Report!AL:AL)), 0)), "Not Found")} | X12: {=IFERROR(INDEX(Load_Booking_Report!N:N, MATCH(TRUE, ISNUMBER(FIND(SUBSTITUTE(C12," ",""), Load_Booking_Report!AL:AL)), 0)), "Not Found")} | Y12: {=IFERROR(INDEX(Load_Booking_Report!V:V, MATCH(TRUE, ISNUMBER(FIND(SUBSTITUTE(C12," ",""), Load_Booking_Report!AL:AL)), 0)), "Not Found")} | Z12: {=IFERROR(INDEX(Load_Booking_Report!BC:BC, MATCH(TRUE, ISNUMBER(FIND(SUBSTITUTE(C12," ",""), Load_Booking_Report!AL:AL)), 0)), "Not Found")}
A13: 31 | B13: 310404 | C13: ANON0000000 | D13: 20 | E13: USNFK | F13: RULED | G13: 27900 | H13: ART | I13: 22G1 | L13: OOG | M13: Full | N13: RULED | P13: =C13 | Q13: {=IFERROR(INDEX(Load_Booking_Report!AC:AC, MATCH(TRUE, ISNUMBER(FIND(SUBSTITUTE(C13," ",""), Load_Booking_Report!AL:AL)), 0)), "Not Found")} | R13: {=IFERROR(INDEX(Load_Booking_Report!C:C, MATCH(TRUE, ISNUMBER(FIND(SUBSTITUTE(C13," ",""), Load_Booking_Report!AL:AL)), 0)), "Not Found")} | S13: {=IFERROR(INDEX(Load_Booking_Report!AG:AG, MATCH(TRUE, ISNUMBER(FIND(SUBSTITUTE(C13," ",""), Load_Booking_Report!AL:AL)), 0)), "Not Found")} | T13: =G13 | U13: {=IFERROR( IF( INDEX(Load_Booking_Report!AM:AM, MATCH(TRUE, ISNUMBER(FIND(SUBSTITUTE(C13," ",""), Load_Booking_Report!AL:AL)), 0) )=0, "", INDEX(Load_Booking_Report!AM:AM, MATCH(TRUE, ISNUMBER(FIND(SUBSTITUTE(C13," ",""), Load_Booking_Report!AL:AL)), 0) ) ), "" )} | V13: {=IFERROR( IF( INDEX(Load_Booking_Report!AR:AR, MATCH(TRUE, ISNUMBER(FIND(SUBSTITUTE(C13," ",""), Load_Booking_Report!AL:AL)), 0) )=0, "", INDEX(Load_Booking_Report!AR:AR, MATCH(TRUE, ISNUMBER(FIND(SUBSTITUTE(C13," ",""), Load_Booking_Report!AL:AL)), 0) ) ), "" )} | W13: {=IFERROR(INDEX(Load_Booking_Report!F:F, MATCH(TRUE, ISNUMBER(FIND(SUBSTITUTE(C13," ",""), Load_Booking_Report!AL:AL)), 0)), "Not Found")} | X13: {=IFERROR(INDEX(Load_Booking_Report!N:N, MATCH(TRUE, ISNUMBER(FIND(SUBSTITUTE(C13," ",""), Load_Booking_Report!AL:AL)), 0)), "Not Found")} | Y13: {=IFERROR(INDEX(Load_Booking_Report!V:V, MATCH(TRUE, ISNUMBER(FIND(SUBSTITUTE(C13," ",""), Load_Booking_Report!AL:AL)), 0)), "Not Found")} | Z13: {=IFERROR(INDEX(Load_Booking_Report!BC:BC, MATCH(TRUE, ISNUMBER(FIND(SUBSTITUTE(C13," ",""), Load_Booking_Report!AL:AL)), 0)), "Not Found")}
... A221: 34 | B221: 340086 | C221: ANON0000000 | D221: 40 | E221: USNFK | F221: RULED | G221: 16170 | H221: ART | I221: 45P3 | L221: OOG | M221: Full | N221: RULED | P221: =C221 | Q221: {=IFERROR(INDEX(Load_Booking_Report!AC:AC, MATCH(TRUE, ISNUMBER(FIND(SUBSTITUTE(C221," ",""), Load_Booking_Report!AL:AL)), 0)), "Not Found")} | R221: {=IFERROR(INDEX(Load_Booking_Report!C:C, MATCH(TRUE, ISNUMBER(FIND(SUBSTITUTE(C221," ",""), Load_Booking_Report!AL:AL)), 0)), "Not Found")} | S221: {=IFERROR(INDEX(Load_Booking_Report!AG:AG, MATCH(TRUE, ISNUMBER(FIND(SUBSTITUTE(C221," ",""), Load_Booking_Report!AL:AL)), 0)), "Not Found")} | T221: =G221 | U221: {=IFERROR( IF( INDEX(Load_Booking_Report!AM:AM, MATCH(TRUE, ISNUMBER(FIND(SUBSTITUTE(C221," ",""), Load_Booking_Report!AL:AL)), 0) )=0, "", INDEX(Load_Booking_Report!AM:AM, MATCH(TRUE, ISNUMBER(FIND(SUBSTITUTE(C221," ",""), Load_Booking_Report!AL:AL)), 0) ) ), "" )} | V221: {=IFERROR( IF( INDEX(Load_Booking_Report!AR:AR, MATCH(TRUE, ISNUMBER(FIND(SUBSTITUTE(C221," ",""), Load_Booking_Report!AL:AL)), 0) )=0, "", INDEX(Load_Booking_Report!AR:AR, MATCH(TRUE, ISNUMBER(FIND(SUBSTITUTE(C221," ",""), Load_Booking_Report!AL:AL)), 0) ) ), "" )} | W221: {=IFERROR(INDEX(Load_Booking_Report!F:F, MATCH(TRUE, ISNUMBER(FIND(SUBSTITUTE(C221," ",""), Load_Booking_Report!AL:AL)), 0)), "Not Found")} | X221: {=IFERROR(INDEX(Load_Booking_Report!N:N, MATCH(TRUE, ISNUMBER(FIND(SUBSTITUTE(C221," ",""), Load_Booking_Report!AL:AL)), 0)), "Not Found")} | Y221: {=IFERROR(INDEX(Load_Booking_Report!V:V, MATCH(TRUE, ISNUMBER(FIND(SUBSTITUTE(C221," ",""), Load_Booking_Report!AL:AL)), 0)), "Not Found")} | Z221: {=IFERROR(INDEX(Load_Booking_Report!BC:BC, MATCH(TRUE, ISNUMBER(FIND(SUBSTITUTE(C221," ",""), Load_Booking_Report!AL:AL)), 0)), "Not Found")}
A222: 26 | B222: 261082 | C222: ANON0000000 | D222: 40 | E222: USHOU | F222: RUBLT | G222: 33230 | H222: ART | I222: 45R0 | K222: -22.0:CEL | L222: 9'6 | M222: Full | N222: RULED | P222: =C222 | Q222: {=IFERROR(INDEX(Load_Booking_Report!AC:AC, MATCH(TRUE, ISNUMBER(FIND(SUBSTITUTE(C222," ",""), Load_Booking_Report!AL:AL)), 0)), "Not Found")} | R222: {=IFERROR(INDEX(Load_Booking_Report!C:C, MATCH(TRUE, ISNUMBER(FIND(SUBSTITUTE(C222," ",""), Load_Booking_Report!AL:AL)), 0)), "Not Found")} | S222: {=IFERROR(INDEX(Load_Booking_Report!AG:AG, MATCH(TRUE, ISNUMBER(FIND(SUBSTITUTE(C222," ",""), Load_Booking_Report!AL:AL)), 0)), "Not Found")} | T222: =G222 | U222: {=IFERROR( IF( INDEX(Load_Booking_Report!AM:AM, MATCH(TRUE, ISNUMBER(FIND(SUBSTITUTE(C222," ",""), Load_Booking_Report!AL:AL)), 0) )=0, "", INDEX(Load_Booking_Report!AM:AM, MATCH(TRUE, ISNUMBER(FIND(SUBSTITUTE(C222," ",""), Load_Booking_Report!AL:AL)), 0) ) ), "" )} | V222: {=IFERROR( IF( INDEX(Load_Booking_Report!AR:AR, MATCH(TRUE, ISNUMBER(FIND(SUBSTITUTE(C222," ",""), Load_Booking_Report!AL:AL)), 0) )=0, "", INDEX(Load_Booking_Report!AR:AR, MATCH(TRUE, ISNUMBER(FIND(SUBSTITUTE(C222," ",""), Load_Booking_Report!AL:AL)), 0) ) ), "" )} | W222: {=IFERROR(INDEX(Load_Booking_Report!F:F, MATCH(TRUE, ISNUMBER(FIND(SUBSTITUTE(C222," ",""), Load_Booking_Report!AL:AL)), 0)), "Not Found")} | X222: {=IFERROR(INDEX(Load_Booking_Report!N:N, MATCH(TRUE, ISNUMBER(FIND(SUBSTITUTE(C222," ",""), Load_Booking_Report!AL:AL)), 0)), "Not Found")} | Y222: {=IFERROR(INDEX(Load_Booking_Report!V:V, MATCH(TRUE, ISNUMBER(FIND(SUBSTITUTE(C222," ",""), Load_Booking_Report!AL:AL)), 0)), "Not Found")} | Z222: {=IFERROR(INDEX(Load_Booking_Report!BC:BC, MATCH(TRUE, ISNUMBER(FIND(SUBSTITUTE(C222," ",""), Load_Booking_Report!AL:AL)), 0)), "Not Found")}
A223: 26 | B223: 260886 | C223: ANON0000000 | D223: 40 | E223: USHOU | F223: RUBLT | G223: 33130 | H223: ART | I223: 45R0 | K223: -22.0:CEL | L223: 9'6 | M223: Full | N223: RULED | P223: =C223 | Q223: {=IFERROR(INDEX(Load_Booking_Report!AC:AC, MATCH(TRUE, ISNUMBER(FIND(SUBSTITUTE(C223," ",""), Load_Booking_Report!AL:AL)), 0)), "Not Found")} | R223: {=IFERROR(INDEX(Load_Booking_Report!C:C, MATCH(TRUE, ISNUMBER(FIND(SUBSTITUTE(C223," ",""), Load_Booking_Report!AL:AL)), 0)), "Not Found")} | S223: {=IFERROR(INDEX(Load_Booking_Report!AG:AG, MATCH(TRUE, ISNUMBER(FIND(SUBSTITUTE(C223," ",""), Load_Booking_Report!AL:AL)), 0)), "Not Found")} | T223: =G223 | U223: {=IFERROR( IF( INDEX(Load_Booking_Report!AM:AM, MATCH(TRUE, ISNUMBER(FIND(SUBSTITUTE(C223," ",""), Load_Booking_Report!AL:AL)), 0) )=0, "", INDEX(Load_Booking_Report!AM:AM, MATCH(TRUE, ISNUMBER(FIND(SUBSTITUTE(C223," ",""), Load_Booking_Report!AL:AL)), 0) ) ), "" )} | V223: {=IFERROR( IF( INDEX(Load_Booking_Report!AR:AR, MATCH(TRUE, ISNUMBER(FIND(SUBSTITUTE(C223," ",""), Load_Booking_Report!AL:AL)), 0) )=0, "", INDEX(Load_Booking_Report!AR:AR, MATCH(TRUE, ISNUMBER(FIND(SUBSTITUTE(C223," ",""), Load_Booking_Report!AL:AL)), 0) ) ), "" )} | W223: {=IFERROR(INDEX(Load_Booking_Report!F:F, MATCH(TRUE, ISNUMBER(FIND(SUBSTITUTE(C223," ",""), Load_Booking_Report!AL:AL)), 0)), "Not Found")} | X223: {=IFERROR(INDEX(Load_Booking_Report!N:N, MATCH(TRUE, ISNUMBER(FIND(SUBSTITUTE(C223," ",""), Load_Booking_Report!AL:AL)), 0)), "Not Found")} | Y223: {=IFERROR(INDEX(Load_Booking_Report!V:V, MATCH(TRUE, ISNUMBER(FIND(SUBSTITUTE(C223," ",""), Load_Booking_Report!AL:AL)), 0)), "Not Found")} | Z223: {=IFERROR(INDEX(Load_Booking_Report!BC:BC, MATCH(TRUE, ISNUMBER(FIND(SUBSTITUTE(C223," ",""), Load_Booking_Report!AL:AL)), 0)), "Not Found")}
A224: 26 | B224: 260984 | C224: ANON0000000 | D224: 40 | E224: USHOU | F224: RUBLT | G224: 33040 | H224: ART | I224: 45R0 | K224: -22.0:CEL | L224: 9'6 | M224: Full | N224: RULED | P224: =C224 | Q224: {=IFERROR(INDEX(Load_Booking_Report!AC:AC, MATCH(TRUE, ISNUMBER(FIND(SUBSTITUTE(C224," ",""), Load_Booking_Report!AL:AL)), 0)), "Not Found")} | R224: {=IFERROR(INDEX(Load_Booking_Report!C:C, MATCH(TRUE, ISNUMBER(FIND(SUBSTITUTE(C224," ",""), Load_Booking_Report!AL:AL)), 0)), "Not Found")} | S224: {=IFERROR(INDEX(Load_Booking_Report!AG:AG, MATCH(TRUE, ISNUMBER(FIND(SUBSTITUTE(C224," ",""), Load_Booking_Report!AL:AL)), 0)), "Not Found")} | T224: =G224 | U224: {=IFERROR( IF( INDEX(Load_Booking_Report!AM:AM, MATCH(TRUE, ISNUMBER(FIND(SUBSTITUTE(C224," ",""), Load_Booking_Report!AL:AL)), 0) )=0, "", INDEX(Load_Booking_Report!AM:AM, MATCH(TRUE, ISNUMBER(FIND(SUBSTITUTE(C224," ",""), Load_Booking_Report!AL:AL)), 0) ) ), "" )} | V224: {=IFERROR( IF( INDEX(Load_Booking_Report!AR:AR, MATCH(TRUE, ISNUMBER(FIND(SUBSTITUTE(C224," ",""), Load_Booking_Report!AL:AL)), 0) )=0, "", INDEX(Load_Booking_Report!AR:AR, MATCH(TRUE, ISNUMBER(FIND(SUBSTITUTE(C224," ",""), Load_Booking_Report!AL:AL)), 0) ) ), "" )} | W224: {=IFERROR(INDEX(Load_Booking_Report!F:F, MATCH(TRUE, ISNUMBER(FIND(SUBSTITUTE(C224," ",""), Load_Booking_Report!AL:AL)), 0)), "Not Found")} | X224: {=IFERROR(INDEX(Load_Booking_Report!N:N, MATCH(TRUE, ISNUMBER(FIND(SUBSTITUTE(C224," ",""), Load_Booking_Report!AL:AL)), 0)), "Not Found")} | Y224: {=IFERROR(INDEX(Load_Booking_Report!V:V, MATCH(TRUE, ISNUMBER(FIND(SUBSTITUTE(C224," ",""), Load_Booking_Report!AL:AL)), 0)), "Not Found")} | Z224: {=IFERROR(INDEX(Load_Booking_Report!BC:BC, MATCH(TRUE, ISNUMBER(FIND(SUBSTITUTE(C224," ",""), Load_Booking_Report!AL:AL)), 0)), "Not Found")}
A225: 26 | B225: 260884 | C225: ANON0000000 | D225: 40 | E225: USHOU | F225: RUBLT | G225: 32864 | H225: ART | I225: 45R0 | K225: -22.0:CEL | L225: 9'6 | M225: Full | N225: RULED | P225: =C225 | Q225: {=IFERROR(INDEX(Load_Booking_Report!AC:AC, MATCH(TRUE, ISNUMBER(FIND(SUBSTITUTE(C225," ",""), Load_Booking_Report!AL:AL)), 0)), "Not Found")} | R225: {=IFERROR(INDEX(Load_Booking_Report!C:C, MATCH(TRUE, ISNUMBER(FIND(SUBSTITUTE(C225," ",""), Load_Booking_Report!AL:AL)), 0)), "Not Found")} | S225: {=IFERROR(INDEX(Load_Booking_Report!AG:AG, MATCH(TRUE, ISNUMBER(FIND(SUBSTITUTE(C225," ",""), Load_Booking_Report!AL:AL)), 0)), "Not Found")} | T225: =G225 | U225: {=IFERROR( IF( INDEX(Load_Booking_Report!AM:AM, MATCH(TRUE, ISNUMBER(FIND(SUBSTITUTE(C225," ",""), Load_Booking_Report!AL:AL)), 0) )=0, "", INDEX(Load_Booking_Report!AM:AM, MATCH(TRUE, ISNUMBER(FIND(SUBSTITUTE(C225," ",""), Load_Booking_Report!AL:AL)), 0) ) ), "" )} | V225: {=IFERROR( IF( INDEX(Load_Booking_Report!AR:AR, MATCH(TRUE, ISNUMBER(FIND(SUBSTITUTE(C225," ",""), Load_Booking_Report!AL:AL)), 0) )=0, "", INDEX(Load_Booking_Report!AR:AR, MATCH(TRUE, ISNUMBER(FIND(SUBSTITUTE(C225," ",""), Load_Booking_Report!AL:AL)), 0) ) ), "" )} | W225: {=IFERROR(INDEX(Load_Booking_Report!F:F, MATCH(TRUE, ISNUMBER(FIND(SUBSTITUTE(C225," ",""), Load_Booking_Report!AL:AL)), 0)), "Not Found")} | X225: {=IFERROR(INDEX(Load_Booking_Report!N:N, MATCH(TRUE, ISNUMBER(FIND(SUBSTITUTE(C225," ",""), Load_Booking_Report!AL:AL)), 0)), "Not Found")} | Y225: {=IFERROR(INDEX(Load_Booking_Report!V:V, MATCH(TRUE, ISNUMBER(FIND(SUBSTITUTE(C225," ",""), Load_Booking_Report!AL:AL)), 0)), "Not Found")} | Z225: {=IFERROR(INDEX(Load_Booking_Report!BC:BC, MATCH(TRUE, ISNUMBER(FIND(SUBSTITUTE(C225," ",""), Load_Booking_Report!AL:AL)), 0)), "Not Found")}
A226: 26 | B226: 260684 | C226: ANON0000000 | D226: 40 | E226: USNYC | F226: RUBLT | G226: 33218 | H226: ART | I226: 45R0 | K226: -22.0:CEL | L226: 9'6 | M226: Full | N226: RULED | P226: =C226 | Q226: {=IFERROR(INDEX(Load_Booking_Report!AC:AC, MATCH(TRUE, ISNUMBER(FIND(SUBSTITUTE(C226," ",""), Load_Booking_Report!AL:AL)), 0)), "Not Found")} | R226: {=IFERROR(INDEX(Load_Booking_Report!C:C, MATCH(TRUE, ISNUMBER(FIND(SUBSTITUTE(C226," ",""), Load_Booking_Report!AL:AL)), 0)), "Not Found")} | S226: {=IFERROR(INDEX(Load_Booking_Report!AG:AG, MATCH(TRUE, ISNUMBER(FIND(SUBSTITUTE(C226," ",""), Load_Booking_Report!AL:AL)), 0)), "Not Found")} | T226: =G226 | U226: {=IFERROR( IF( INDEX(Load_Booking_Report!AM:AM, MATCH(TRUE, ISNUMBER(FIND(SUBSTITUTE(C226," ",""), Load_Booking_Report!AL:AL)), 0) )=0, "", INDEX(Load_Booking_Report!AM:AM, MATCH(TRUE, ISNUMBER(FIND(SUBSTITUTE(C226," ",""), Load_Booking_Report!AL:AL)), 0) ) ), "" )} | V226: {=IFERROR( IF( INDEX(Load_Booking_Report!AR:AR, MATCH(TRUE, ISNUMBER(FIND(SUBSTITUTE(C226," ",""), Load_Booking_Report!AL:AL)), 0) )=0, "", INDEX(Load_Booking_Report!AR:AR, MATCH(TRUE, ISNUMBER(FIND(SUBSTITUTE(C226," ",""), Load_Booking_Report!AL:AL)), 0) ) ), "" )} | W226: {=IFERROR(INDEX(Load_Booking_Report!F:F, MATCH(TRUE, ISNUMBER(FIND(SUBSTITUTE(C226," ",""), Load_Booking_Report!AL:AL)), 0)), "Not Found")} | X226: {=IFERROR(INDEX(Load_Booking_Report!N:N, MATCH(TRUE, ISNUMBER(FIND(SUBSTITUTE(C226," ",""), Load_Booking_Report!AL:AL)), 0)), "Not Found")} | Y226: {=IFERROR(INDEX(Load_Booking_Report!V:V, MATCH(TRUE, ISNUMBER(FIND(SUBSTITUTE(C226," ",""), Load_Booking_Report!AL:AL)), 0)), "Not Found")} | Z226: {=IFERROR(INDEX(Load_Booking_Report!BC:BC, MATCH(TRUE, ISNUMBER(FIND(SUBSTITUTE(C226," ",""), Load_Booking_Report!AL:AL)), 0)), "Not Found")}
A227: 34 | B227: 340884 | C227: ANON0000000 | D227: 40 | E227: USNFK | F227: RULED | G227: 29976 | H227: ART | I227: 45R1 | K227: -1.4:CEL | L227: OOG | M227: Full | N227: RULED | P227: =C227 | Q227: {=IFERROR(INDEX(Load_Booking_Report!AC:AC, MATCH(TRUE, ISNUMBER(FIND(SUBSTITUTE(C227," ",""), Load_Booking_Report!AL:AL)), 0)), "Not Found")} | R227: {=IFERROR(INDEX(Load_Booking_Report!C:C, MATCH(TRUE, ISNUMBER(FIND(SUBSTITUTE(C227," ",""), Load_Booking_Report!AL:AL)), 0)), "Not Found")} | S227: {=IFERROR(INDEX(Load_Booking_Report!AG:AG, MATCH(TRUE, ISNUMBER(FIND(SUBSTITUTE(C227," ",""), Load_Booking_Report!AL:AL)), 0)), "Not Found")} | T227: =G227 | U227: {=IFERROR( IF( INDEX(Load_Booking_Report!AM:AM, MATCH(TRUE, ISNUMBER(FIND(SUBSTITUTE(C227," ",""), Load_Booking_Report!AL:AL)), 0) )=0, "", INDEX(Load_Booking_Report!AM:AM, MATCH(TRUE, ISNUMBER(FIND(SUBSTITUTE(C227," ",""), Load_Booking_Report!AL:AL)), 0) ) ), "" )} | V227: {=IFERROR( IF( INDEX(Load_Booking_Report!AR:AR, MATCH(TRUE, ISNUMBER(FIND(SUBSTITUTE(C227," ",""), Load_Booking_Report!AL:AL)), 0) )=0, "", INDEX(Load_Booking_Report!AR:AR, MATCH(TRUE, ISNUMBER(FIND(SUBSTITUTE(C227," ",""), Load_Booking_Report!AL:AL)), 0) ) ), "" )} | W227: {=IFERROR(INDEX(Load_Booking_Report!F:F, MATCH(TRUE, ISNUMBER(FIND(SUBSTITUTE(C227," ",""), Load_Booking_Report!AL:AL)), 0)), "Not Found")} | X227: {=IFERROR(INDEX(Load_Booking_Report!N:N, MATCH(TRUE, ISNUMBER(FIND(SUBSTITUTE(C227," ",""), Load_Booking_Report!AL:AL)), 0)), "Not Found")} | Y227: {=IFERROR(INDEX(Load_Booking_Report!V:V, MATCH(TRUE, ISNUMBER(FIND(SUBSTITUTE(C227," ",""), Load_Booking_Report!AL:AL)), 0)), "Not Found")} | Z227: {=IFERROR(INDEX(Load_Booking_Report!BC:BC, MATCH(TRUE, ISNUMBER(FIND(SUBSTITUTE(C227," ",""), Load_Booking_Report!AL:AL)), 0)), "Not Found")}
A228: 34 | B228: 340982 | C228: ANON0000000 | D228: 40 | E228: USHOU | F228: RULED | G228: 32158 | H228: ART | I228: 45R1 | K228: -18.0:CEL | L228: 9'6 | M228: Full | N228: RULED | P228: =C228 | Q228: {=IFERROR(INDEX(Load_Booking_Report!AC:AC, MATCH(TRUE, ISNUMBER(FIND(SUBSTITUTE(C228," ",""), Load_Booking_Report!AL:AL)), 0)), "Not Found")} | R228: {=IFERROR(INDEX(Load_Booking_Report!C:C, MATCH(TRUE, ISNUMBER(FIND(SUBSTITUTE(C228," ",""), Load_Booking_Report!AL:AL)), 0)), "Not Found")} | S228: {=IFERROR(INDEX(Load_Booking_Report!AG:AG, MATCH(TRUE, ISNUMBER(FIND(SUBSTITUTE(C228," ",""), Load_Booking_Report!AL:AL)), 0)), "Not Found")} | T228: =G228 | U228: {=IFERROR( IF( INDEX(Load_Booking_Report!AM:AM, MATCH(TRUE, ISNUMBER(FIND(SUBSTITUTE(C228," ",""), Load_Booking_Report!AL:AL)), 0) )=0, "", INDEX(Load_Booking_Report!AM:AM, MATCH(TRUE, ISNUMBER(FIND(SUBSTITUTE(C228," ",""), Load_Booking_Report!AL:AL)), 0) ) ), "" )} | V228: {=IFERROR( IF( INDEX(Load_Booking_Report!AR:AR, MATCH(TRUE, ISNUMBER(FIND(SUBSTITUTE(C228," ",""), Load_Booking_Report!AL:AL)), 0) )=0, "", INDEX(Load_Booking_Report!AR:AR, MATCH(TRUE, ISNUMBER(FIND(SUBSTITUTE(C228," ",""), Load_Booking_Report!AL:AL)), 0) ) ), "" )} | W228: {=IFERROR(INDEX(Load_Booking_Report!F:F, MATCH(TRUE, ISNUMBER(FIND(SUBSTITUTE(C228," ",""), Load_Booking_Report!AL:AL)), 0)), "Not Found")} | X228: {=IFERROR(INDEX(Load_Booking_Report!N:N, MATCH(TRUE, ISNUMBER(FIND(SUBSTITUTE(C228," ",""), Load_Booking_Report!AL:AL)), 0)), "Not Found")} | Y228: {=IFERROR(INDEX(Load_Booking_Report!V:V, MATCH(TRUE, ISNUMBER(FIND(SUBSTITUTE(C228," ",""), Load_Booking_Report!AL:AL)), 0)), "Not Found")} | Z228: {=IFERROR(INDEX(Load_Booking_Report!BC:BC, MATCH(TRUE, ISNUMBER(FIND(SUBSTITUTE(C228," ",""), Load_Booking_Report!AL:AL)), 0)), "Not Found")}
A229: 26 | B229: 260384 | C229: ANON0000000 | D229: 40 | E229: USHOU | F229: RULED | G229: 27679 | H229: ART | I229: 45R1 | K229: 0.0:CEL | L229: 9'6 | M229: Full | N229: RULED | P229: =C229 | Q229: {=IFERROR(INDEX(Load_Booking_Report!AC:AC, MATCH(TRUE, ISNUMBER(FIND(SUBSTITUTE(C229," ",""), Load_Booking_Report!AL:AL)), 0)), "Not Found")} | R229: {=IFERROR(INDEX(Load_Booking_Report!C:C, MATCH(TRUE, ISNUMBER(FIND(SUBSTITUTE(C229," ",""), Load_Booking_Report!AL:AL)), 0)), "Not Found")} | S229: {=IFERROR(INDEX(Load_Booking_Report!AG:AG, MATCH(TRUE, ISNUMBER(FIND(SUBSTITUTE(C229," ",""), Load_Booking_Report!AL:AL)), 0)), "Not Found")} | T229: =G229 | U229: {=IFERROR( IF( INDEX(Load_Booking_Report!AM:AM, MATCH(TRUE, ISNUMBER(FIND(SUBSTITUTE(C229," ",""), Load_Booking_Report!AL:AL)), 0) )=0, "", INDEX(Load_Booking_Report!AM:AM, MATCH(TRUE, ISNUMBER(FIND(SUBSTITUTE(C229," ",""), Load_Booking_Report!AL:AL)), 0) ) ), "" )} | V229: {=IFERROR( IF( INDEX(Load_Booking_Report!AR:AR, MATCH(TRUE, ISNUMBER(FIND(SUBSTITUTE(C229," ",""), Load_Booking_Report!AL:AL)), 0) )=0, "", INDEX(Load_Booking_Report!AR:AR, MATCH(TRUE, ISNUMBER(FIND(SUBSTITUTE(C229," ",""), Load_Booking_Report!AL:AL)), 0) ) ), "" )} | W229: {=IFERROR(INDEX(Load_Booking_Report!F:F, MATCH(TRUE, ISNUMBER(FIND(SUBSTITUTE(C229," ",""), Load_Booking_Report!AL:AL)), 0)), "Not Found")} | X229: {=IFERROR(INDEX(Load_Booking_Report!N:N, MATCH(TRUE, ISNUMBER(FIND(SUBSTITUTE(C229," ",""), Load_Booking_Report!AL:AL)), 0)), "Not Found")} | Y229: {=IFERROR(INDEX(Load_Booking_Report!V:V, MATCH(TRUE, ISNUMBER(FIND(SUBSTITUTE(C229," ",""), Load_Booking_Report!AL:AL)), 0)), "Not Found")} | Z229: {=IFERROR(INDEX(Load_Booking_Report!BC:BC, MATCH(TRUE, ISNUMBER(FIND(SUBSTITUTE(C229," ",""), Load_Booking_Report!AL:AL)), 0)), "Not Found")}
A230: 26 | B230: 260882 | C230: ANON0000000 | D230: 40 | E230: USHOU | F230: RUBLT | G230: 33190 | H230: ART | I230: 45R1 | K230: -22.0:CEL | L230: 9'6 | M230: Full | N230: RULED | P230: =C230 | Q230: {=IFERROR(INDEX(Load_Booking_Report!AC:AC, MATCH(TRUE, ISNUMBER(FIND(SUBSTITUTE(C230," ",""), Load_Booking_Report!AL:AL)), 0)), "Not Found")} | R230: {=IFERROR(INDEX(Load_Booking_Report!C:C, MATCH(TRUE, ISNUMBER(FIND(SUBSTITUTE(C230," ",""), Load_Booking_Report!AL:AL)), 0)), "Not Found")} | S230: {=IFERROR(INDEX(Load_Booking_Report!AG:AG, MATCH(TRUE, ISNUMBER(FIND(SUBSTITUTE(C230," ",""), Load_Booking_Report!AL:AL)), 0)), "Not Found")} | T230: =G230 | U230: {=IFERROR( IF( INDEX(Load_Booking_Report!AM:AM, MATCH(TRUE, ISNUMBER(FIND(SUBSTITUTE(C230," ",""), Load_Booking_Report!AL:AL)), 0) )=0, "", INDEX(Load_Booking_Report!AM:AM, MATCH(TRUE, ISNUMBER(FIND(SUBSTITUTE(C230," ",""), Load_Booking_Report!AL:AL)), 0) ) ), "" )} | V230: {=IFERROR( IF( INDEX(Load_Booking_Report!AR:AR, MATCH(TRUE, ISNUMBER(FIND(SUBSTITUTE(C230," ",""), Load_Booking_Report!AL:AL)), 0) )=0, "", INDEX(Load_Booking_Report!AR:AR, MATCH(TRUE, ISNUMBER(FIND(SUBSTITUTE(C230," ",""), Load_Booking_Report!AL:AL)), 0) ) ), "" )} | W230: {=IFERROR(INDEX(Load_Booking_Report!F:F, MATCH(TRUE, ISNUMBER(FIND(SUBSTITUTE(C230," ",""), Load_Booking_Report!AL:AL)), 0)), "Not Found")} | X230: {=IFERROR(INDEX(Load_Booking_Report!N:N, MATCH(TRUE, ISNUMBER(FIND(SUBSTITUTE(C230," ",""), Load_Booking_Report!AL:AL)), 0)), "Not Found")} | Y230: {=IFERROR(INDEX(Load_Booking_Report!V:V, MATCH(TRUE, ISNUMBER(FIND(SUBSTITUTE(C230," ",""), Load_Booking_Report!AL:AL)), 0)), "Not Found")} | Z230: {=IFERROR(INDEX(Load_Booking_Report!BC:BC, MATCH(TRUE, ISNUMBER(FIND(SUBSTITUTE(C230," ",""), Load_Booking_Report!AL:AL)), 0)), "Not Found")}
A231: 34 | B231: 341084 | C231: ANON0000000 | D231: 40 | E231: USNFK | F231: RULED | G231: 25367 | H231: ART | I231: 45R1 | K231: 10.0:CEL | L231: OOG | M231: Full | N231: RULED | P231: =C231 | Q231: {=IFERROR(INDEX(Load_Booking_Report!AC:AC, MATCH(TRUE, ISNUMBER(FIND(SUBSTITUTE(C231," ",""), Load_Booking_Report!AL:AL)), 0)), "Not Found")} | R231: {=IFERROR(INDEX(Load_Booking_Report!C:C, MATCH(TRUE, ISNUMBER(FIND(SUBSTITUTE(C231," ",""), Load_Booking_Report!AL:AL)), 0)), "Not Found")} | S231: {=IFERROR(INDEX(Load_Booking_Report!AG:AG, MATCH(TRUE, ISNUMBER(FIND(SUBSTITUTE(C231," ",""), Load_Booking_Report!AL:AL)), 0)), "Not Found")} | T231: =G231 | U231: {=IFERROR( IF( INDEX(Load_Booking_Report!AM:AM, MATCH(TRUE, ISNUMBER(FIND(SUBSTITUTE(C231," ",""), Load_Booking_Report!AL:AL)), 0) )=0, "", INDEX(Load_Booking_Report!AM:AM, MATCH(TRUE, ISNUMBER(FIND(SUBSTITUTE(C231," ",""), Load_Booking_Report!AL:AL)), 0) ) ), "" )} | V231: {=IFERROR( IF( INDEX(Load_Booking_Report!AR:AR, MATCH(TRUE, ISNUMBER(FIND(SUBSTITUTE(C231," ",""), Load_Booking_Report!AL:AL)), 0) )=0, "", INDEX(Load_Booking_Report!AR:AR, MATCH(TRUE, ISNUMBER(FIND(SUBSTITUTE(C231," ",""), Load_Booking_Report!AL:AL)), 0) ) ), "" )} | W231: {=IFERROR(INDEX(Load_Booking_Report!F:F, MATCH(TRUE, ISNUMBER(FIND(SUBSTITUTE(C231," ",""), Load_Booking_Report!AL:AL)), 0)), "Not Found")} | X231: {=IFERROR(INDEX(Load_Booking_Report!N:N, MATCH(TRUE, ISNUMBER(FIND(SUBSTITUTE(C231," ",""), Load_Booking_Report!AL:AL)), 0)), "Not Found")} | Y231: {=IFERROR(INDEX(Load_Booking_Report!V:V, MATCH(TRUE, ISNUMBER(FIND(SUBSTITUTE(C231," ",""), Load_Booking_Report!AL:AL)), 0)), "Not Found")} | Z231: {=IFERROR(INDEX(Load_Booking_Report!BC:BC, MATCH(TRUE, ISNUMBER(FIND(SUBSTITUTE(C231," ",""), Load_Booking_Report!AL:AL)), 0)), "Not Found")}
A232: 34 | B232: 340682 | C232: ANON0000000 | D232: 40 | E232: USHOU | F232: RULED | G232: 32356 | H232: ART | I232: 45R1 | K232: -18.0:CEL | L232: 9'6 | M232: Full | N232: RULED | P232: =C232 | Q232: {=IFERROR(INDEX(Load_Booking_Report!AC:AC, MATCH(TRUE, ISNUMBER(FIND(SUBSTITUTE(C232," ",""), Load_Booking_Report!AL:AL)), 0)), "Not Found")} | R232: {=IFERROR(INDEX(Load_Booking_Report!C:C, MATCH(TRUE, ISNUMBER(FIND(SUBSTITUTE(C232," ",""), Load_Booking_Report!AL:AL)), 0)), "Not Found")} | S232: {=IFERROR(INDEX(Load_Booking_Report!AG:AG, MATCH(TRUE, ISNUMBER(FIND(SUBSTITUTE(C232," ",""), Load_Booking_Report!AL:AL)), 0)), "Not Found")} | T232: =G232 | U232: {=IFERROR( IF( INDEX(Load_Booking_Report!AM:AM, MATCH(TRUE, ISNUMBER(FIND(SUBSTITUTE(C232," ",""), Load_Booking_Report!AL:AL)), 0) )=0, "", INDEX(Load_Booking_Report!AM:AM, MATCH(TRUE, ISNUMBER(FIND(SUBSTITUTE(C232," ",""), Load_Booking_Report!AL:AL)), 0) ) ), "" )} | V232: {=IFERROR( IF( INDEX(Load_Booking_Report!AR:AR, MATCH(TRUE, ISNUMBER(FIND(SUBSTITUTE(C232," ",""), Load_Booking_Report!AL:AL)), 0) )=0, "", INDEX(Load_Booking_Report!AR:AR, MATCH(TRUE, ISNUMBER(FIND(SUBSTITUTE(C232," ",""), Load_Booking_Report!AL:AL)), 0) ) ), "" )} | W232: {=IFERROR(INDEX(Load_Booking_Report!F:F, MATCH(TRUE, ISNUMBER(FIND(SUBSTITUTE(C232," ",""), Load_Booking_Report!AL:AL)), 0)), "Not Found")} | X232: {=IFERROR(INDEX(Load_Booking_Report!N:N, MATCH(TRUE, ISNUMBER(FIND(SUBSTITUTE(C232," ",""), Load_Booking_Report!AL:AL)), 0)), "Not Found")} | Y232: {=IFERROR(INDEX(Load_Booking_Report!V:V, MATCH(TRUE, ISNUMBER(FIND(SUBSTITUTE(C232," ",""), Load_Booking_Report!AL:AL)), 0)), "Not Found")} | Z232: {=IFERROR(INDEX(Load_Booking_Report!BC:BC, MATCH(TRUE, ISNUMBER(FIND(SUBSTITUTE(C232," ",""), Load_Booking_Report!AL:AL)), 0)), "Not Found")}
A233: 40 | B233: 400882 | C233: ANON0000000 | D233: 40 | E233: USHOU | F233: RUBLT | G233: 33190 | H233: ART | I233: 45R1 | K233: -22.0:CEL | L233: 9'6 | M233: Full | N233: RULED | P233: =C233 | Q233: {=IFERROR(INDEX(Load_Booking_Report!AC:AC, MATCH(TRUE, ISNUMBER(FIND(SUBSTITUTE(C233," ",""), Load_Booking_Report!AL:AL)), 0)), "Not Found")} | R233: {=IFERROR(INDEX(Load_Booking_Report!C:C, MATCH(TRUE, ISNUMBER(FIND(SUBSTITUTE(C233," ",""), Load_Booking_Report!AL:AL)), 0)), "Not Found")} | S233: {=IFERROR(INDEX(Load_Booking_Report!AG:AG, MATCH(TRUE, ISNUMBER(FIND(SUBSTITUTE(C233," ",""), Load_Booking_Report!AL:AL)), 0)), "Not Found")} | T233: =G233 | U233: {=IFERROR( IF( INDEX(Load_Booking_Report!AM:AM, MATCH(TRUE, ISNUMBER(FIND(SUBSTITUTE(C233," ",""), Load_Booking_Report!AL:AL)), 0) )=0, "", INDEX(Load_Booking_Report!AM:AM, MATCH(TRUE, ISNUMBER(FIND(SUBSTITUTE(C233," ",""), Load_Booking_Report!AL:AL)), 0) ) ), "" )} | V233: {=IFERROR( IF( INDEX(Load_Booking_Report!AR:AR, MATCH(TRUE, ISNUMBER(FIND(SUBSTITUTE(C233," ",""), Load_Booking_Report!AL:AL)), 0) )=0, "", INDEX(Load_Booking_Report!AR:AR, MATCH(TRUE, ISNUMBER(FIND(SUBSTITUTE(C233," ",""), Load_Booking_Report!AL:AL)), 0) ) ), "" )} | W233: {=IFERROR(INDEX(Load_Booking_Report!F:F, MATCH(TRUE, ISNUMBER(FIND(SUBSTITUTE(C233," ",""), Load_Booking_Report!AL:AL)), 0)), "Not Found")} | X233: {=IFERROR(INDEX(Load_Booking_Report!N:N, MATCH(TRUE, ISNUMBER(FIND(SUBSTITUTE(C233," ",""), Load_Booking_Report!AL:AL)), 0)), "Not Found")} | Y233: {=IFERROR(INDEX(Load_Booking_Report!V:V, MATCH(TRUE, ISNUMBER(FIND(SUBSTITUTE(C233," ",""), Load_Booking_Report!AL:AL)), 0)), "Not Found")} | Z233: {=IFERROR(INDEX(Load_Booking_Report!BC:BC, MATCH(TRUE, ISNUMBER(FIND(SUBSTITUTE(C233," ",""), Load_Booking_Report!AL:AL)), 0)), "Not Found")}
... A273: 26 | B273: 260782 | C273: ANON0000000 | D273: 40 | E273: USNYC | F273: RUBLT | G273: 32650 | H273: ART | I273: 45RH | K273: -18.0:CEL | L273: 9'6 | M273: Full | N273: RULED | P273: =C273 | Q273: {=IFERROR(INDEX(Load_Booking_Report!AC:AC, MATCH(TRUE, ISNUMBER(FIND(SUBSTITUTE(C273," ",""), Load_Booking_Report!AL:AL)), 0)), "Not Found")} | R273: {=IFERROR(INDEX(Load_Booking_Report!C:C, MATCH(TRUE, ISNUMBER(FIND(SUBSTITUTE(C273," ",""), Load_Booking_Report!AL:AL)), 0)), "Not Found")} | S273: {=IFERROR(INDEX(Load_Booking_Report!AG:AG, MATCH(TRUE, ISNUMBER(FIND(SUBSTITUTE(C273," ",""), Load_Booking_Report!AL:AL)), 0)), "Not Found")} | T273: =G273 | U273: {=IFERROR( IF( INDEX(Load_Booking_Report!AM:AM, MATCH(TRUE, ISNUMBER(FIND(SUBSTITUTE(C273," ",""), Load_Booking_Report!AL:AL)), 0) )=0, "", INDEX(Load_Booking_Report!AM:AM, MATCH(TRUE, ISNUMBER(FIND(SUBSTITUTE(C273," ",""), Load_Booking_Report!AL:AL)), 0) ) ), "" )} | V273: {=IFERROR( IF( INDEX(Load_Booking_Report!AR:AR, MATCH(TRUE, ISNUMBER(FIND(SUBSTITUTE(C273," ",""), Load_Booking_Report!AL:AL)), 0) )=0, "", INDEX(Load_Booking_Report!AR:AR, MATCH(TRUE, ISNUMBER(FIND(SUBSTITUTE(C273," ",""), Load_Booking_Report!AL:AL)), 0) ) ), "" )} | W273: {=IFERROR(INDEX(Load_Booking_Report!F:F, MATCH(TRUE, ISNUMBER(FIND(SUBSTITUTE(C273," ",""), Load_Booking_Report!AL:AL)), 0)), "Not Found")} | X273: {=IFERROR(INDEX(Load_Booking_Report!N:N, MATCH(TRUE, ISNUMBER(FIND(SUBSTITUTE(C273," ",""), Load_Booking_Report!AL:AL)), 0)), "Not Found")} | Y273: {=IFERROR(INDEX(Load_Booking_Report!V:V, MATCH(TRUE, ISNUMBER(FIND(SUBSTITUTE(C273," ",""), Load_Booking_Report!AL:AL)), 0)), "Not Found")} | Z273: {=IFERROR(INDEX(Load_Booking_Report!BC:BC, MATCH(TRUE, ISNUMBER(FIND(SUBSTITUTE(C273," ",""), Load_Booking_Report!AL:AL)), 0)), "Not Found")}
A274: 31 | B274: 310402 | C274: ANON0000000 | D274: 20 | E274: USNFK | F274: RULED | G274: 26770 | H274: ART | I274: 22DC | L274: OOG | M274: Full | N274: RULED | P274: =C274 | Q274: {=IFERROR(INDEX(Load_Booking_Report!AC:AC, MATCH(TRUE, ISNUMBER(FIND(SUBSTITUTE(C274," ",""), Load_Booking_Report!AL:AL)), 0)), "Not Found")} | R274: {=IFERROR(INDEX(Load_Booking_Report!C:C, MATCH(TRUE, ISNUMBER(FIND(SUBSTITUTE(C274," ",""), Load_Booking_Report!AL:AL)), 0)), "Not Found")} | S274: {=IFERROR(INDEX(Load_Booking_Report!AG:AG, MATCH(TRUE, ISNUMBER(FIND(SUBSTITUTE(C274," ",""), Load_Booking_Report!AL:AL)), 0)), "Not Found")} | T274: =G274 | U274: {=IFERROR( IF( INDEX(Load_Booking_Report!AM:AM, MATCH(TRUE, ISNUMBER(FIND(SUBSTITUTE(C274," ",""), Load_Booking_Report!AL:AL)), 0) )=0, "", INDEX(Load_Booking_Report!AM:AM, MATCH(TRUE, ISNUMBER(FIND(SUBSTITUTE(C274," ",""), Load_Booking_Report!AL:AL)), 0) ) ), "" )} | V274: {=IFERROR( IF( INDEX(Load_Booking_Report!AR:AR, MATCH(TRUE, ISNUMBER(FIND(SUBSTITUTE(C274," ",""), Load_Booking_Report!AL:AL)), 0) )=0, "", INDEX(Load_Booking_Report!AR:AR, MATCH(TRUE, ISNUMBER(FIND(SUBSTITUTE(C274," ",""), Load_Booking_Report!AL:AL)), 0) ) ), "" )} | W274: {=IFERROR(INDEX(Load_Booking_Report!F:F, MATCH(TRUE, ISNUMBER(FIND(SUBSTITUTE(C274," ",""), Load_Booking_Report!AL:AL)), 0)), "Not Found")} | X274: {=IFERROR(INDEX(Load_Booking_Report!N:N, MATCH(TRUE, ISNUMBER(FIND(SUBSTITUTE(C274," ",""), Load_Booking_Report!AL:AL)), 0)), "Not Found")} | Y274: {=IFERROR(INDEX(Load_Booking_Report!V:V, MATCH(TRUE, ISNUMBER(FIND(SUBSTITUTE(C274," ",""), Load_Booking_Report!AL:AL)), 0)), "Not Found")} | Z274: {=IFERROR(INDEX(Load_Booking_Report!BC:BC, MATCH(TRUE, ISNUMBER(FIND(SUBSTITUTE(C274," ",""), Load_Booking_Report!AL:AL)), 0)), "Not Found")}
A275: 31 | B275: 310602 | C275: ANON0000000 | D275: 20 | E275: USNFK | F275: RULED | G275: 26680 | H275: ART | I275: 22DC | L275: OOG | M275: Full | N275: RULED | P275: =C275 | Q275: {=IFERROR(INDEX(Load_Booking_Report!AC:AC, MATCH(TRUE, ISNUMBER(FIND(SUBSTITUTE(C275," ",""), Load_Booking_Report!AL:AL)), 0)), "Not Found")} | R275: {=IFERROR(INDEX(Load_Booking_Report!C:C, MATCH(TRUE, ISNUMBER(FIND(SUBSTITUTE(C275," ",""), Load_Booking_Report!AL:AL)), 0)), "Not Found")} | S275: {=IFERROR(INDEX(Load_Booking_Report!AG:AG, MATCH(TRUE, ISNUMBER(FIND(SUBSTITUTE(C275," ",""), Load_Booking_Report!AL:AL)), 0)), "Not Found")} | T275: =G275 | U275: {=IFERROR( IF( INDEX(Load_Booking_Report!AM:AM, MATCH(TRUE, ISNUMBER(FIND(SUBSTITUTE(C275," ",""), Load_Booking_Report!AL:AL)), 0) )=0, "", INDEX(Load_Booking_Report!AM:AM, MATCH(TRUE, ISNUMBER(FIND(SUBSTITUTE(C275," ",""), Load_Booking_Report!AL:AL)), 0) ) ), "" )} | V275: {=IFERROR( IF( INDEX(Load_Booking_Report!AR:AR, MATCH(TRUE, ISNUMBER(FIND(SUBSTITUTE(C275," ",""), Load_Booking_Report!AL:AL)), 0) )=0, "", INDEX(Load_Booking_Report!AR:AR, MATCH(TRUE, ISNUMBER(FIND(SUBSTITUTE(C275," ",""), Load_Booking_Report!AL:AL)), 0) ) ), "" )} | W275: {=IFERROR(INDEX(Load_Booking_Report!F:F, MATCH(TRUE, ISNUMBER(FIND(SUBSTITUTE(C275," ",""), Load_Booking_Report!AL:AL)), 0)), "Not Found")} | X275: {=IFERROR(INDEX(Load_Booking_Report!N:N, MATCH(TRUE, ISNUMBER(FIND(SUBSTITUTE(C275," ",""), Load_Booking_Report!AL:AL)), 0)), "Not Found")} | Y275: {=IFERROR(INDEX(Load_Booking_Report!V:V, MATCH(TRUE, ISNUMBER(FIND(SUBSTITUTE(C275," ",""), Load_Booking_Report!AL:AL)), 0)), "Not Found")} | Z275: {=IFERROR(INDEX(Load_Booking_Report!BC:BC, MATCH(TRUE, ISNUMBER(FIND(SUBSTITUTE(C275," ",""), Load_Booking_Report!AL:AL)), 0)), "Not Found")}
A276: 31 | B276: 310804 | C276: ANON0000000 | D276: 20 | E276: USNFK | F276: RULED | G276: 25972 | H276: ART | I276: 22DC | L276: OOG | M276: Full | N276: RULED | P276: =C276 | Q276: {=IFERROR(INDEX(Load_Booking_Report!AC:AC, MATCH(TRUE, ISNUMBER(FIND(SUBSTITUTE(C276," ",""), Load_Booking_Report!AL:AL)), 0)), "Not Found")} | R276: {=IFERROR(INDEX(Load_Booking_Report!C:C, MATCH(TRUE, ISNUMBER(FIND(SUBSTITUTE(C276," ",""), Load_Booking_Report!AL:AL)), 0)), "Not Found")} | S276: {=IFERROR(INDEX(Load_Booking_Report!AG:AG, MATCH(TRUE, ISNUMBER(FIND(SUBSTITUTE(C276," ",""), Load_Booking_Report!AL:AL)), 0)), "Not Found")} | T276: =G276 | U276: {=IFERROR( IF( INDEX(Load_Booking_Report!AM:AM, MATCH(TRUE, ISNUMBER(FIND(SUBSTITUTE(C276," ",""), Load_Booking_Report!AL:AL)), 0) )=0, "", INDEX(Load_Booking_Report!AM:AM, MATCH(TRUE, ISNUMBER(FIND(SUBSTITUTE(C276," ",""), Load_Booking_Report!AL:AL)), 0) ) ), "" )} | V276: {=IFERROR( IF( INDEX(Load_Booking_Report!AR:AR, MATCH(TRUE, ISNUMBER(FIND(SUBSTITUTE(C276," ",""), Load_Booking_Report!AL:AL)), 0) )=0, "", INDEX(Load_Booking_Report!AR:AR, MATCH(TRUE, ISNUMBER(FIND(SUBSTITUTE(C276," ",""), Load_Booking_Report!AL:AL)), 0) ) ), "" )} | W276: {=IFERROR(INDEX(Load_Booking_Report!F:F, MATCH(TRUE, ISNUMBER(FIND(SUBSTITUTE(C276," ",""), Load_Booking_Report!AL:AL)), 0)), "Not Found")} | X276: {=IFERROR(INDEX(Load_Booking_Report!N:N, MATCH(TRUE, ISNUMBER(FIND(SUBSTITUTE(C276," ",""), Load_Booking_Report!AL:AL)), 0)), "Not Found")} | Y276: {=IFERROR(INDEX(Load_Booking_Report!V:V, MATCH(TRUE, ISNUMBER(FIND(SUBSTITUTE(C276," ",""), Load_Booking_Report!AL:AL)), 0)), "Not Found")} | Z276: {=IFERROR(INDEX(Load_Booking_Report!BC:BC, MATCH(TRUE, ISNUMBER(FIND(SUBSTITUTE(C276," ",""), Load_Booking_Report!AL:AL)), 0)), "Not Found")}
A277: 17 | B277: 170502 | C277: ANON0000000 | D277: 20 | E277: USNFK | F277: RULED | G277: 26725 | H277: ART | I277: 22DC | L277: OOG | M277: Full | N277: RULED | P277: =C277 | Q277: {=IFERROR(INDEX(Load_Booking_Report!AC:AC, MATCH(TRUE, ISNUMBER(FIND(SUBSTITUTE(C277," ",""), Load_Booking_Report!AL:AL)), 0)), "Not Found")} | R277: {=IFERROR(INDEX(Load_Booking_Report!C:C, MATCH(TRUE, ISNUMBER(FIND(SUBSTITUTE(C277," ",""), Load_Booking_Report!AL:AL)), 0)), "Not Found")} | S277: {=IFERROR(INDEX(Load_Booking_Report!AG:AG, MATCH(TRUE, ISNUMBER(FIND(SUBSTITUTE(C277," ",""), Load_Booking_Report!AL:AL)), 0)), "Not Found")} | T277: =G277 | U277: {=IFERROR( IF( INDEX(Load_Booking_Report!AM:AM, MATCH(TRUE, ISNUMBER(FIND(SUBSTITUTE(C277," ",""), Load_Booking_Report!AL:AL)), 0) )=0, "", INDEX(Load_Booking_Report!AM:AM, MATCH(TRUE, ISNUMBER(FIND(SUBSTITUTE(C277," ",""), Load_Booking_Report!AL:AL)), 0) ) ), "" )} | V277: {=IFERROR( IF( INDEX(Load_Booking_Report!AR:AR, MATCH(TRUE, ISNUMBER(FIND(SUBSTITUTE(C277," ",""), Load_Booking_Report!AL:AL)), 0) )=0, "", INDEX(Load_Booking_Report!AR:AR, MATCH(TRUE, ISNUMBER(FIND(SUBSTITUTE(C277," ",""), Load_Booking_Report!AL:AL)), 0) ) ), "" )} | W277: {=IFERROR(INDEX(Load_Booking_Report!F:F, MATCH(TRUE, ISNUMBER(FIND(SUBSTITUTE(C277," ",""), Load_Booking_Report!AL:AL)), 0)), "Not Found")} | X277: {=IFERROR(INDEX(Load_Booking_Report!N:N, MATCH(TRUE, ISNUMBER(FIND(SUBSTITUTE(C277," ",""), Load_Booking_Report!AL:AL)), 0)), "Not Found")} | Y277: {=IFERROR(INDEX(Load_Booking_Report!V:V, MATCH(TRUE, ISNUMBER(FIND(SUBSTITUTE(C277," ",""), Load_Booking_Report!AL:AL)), 0)), "Not Found")} | Z277: {=IFERROR(INDEX(Load_Booking_Report!BC:BC, MATCH(TRUE, ISNUMBER(FIND(SUBSTITUTE(C277," ",""), Load_Booking_Report!AL:AL)), 0)), "Not Found")}
A278: 19 | B278: 190702 | C278: ANON0000000 | D278: 20 | E278: USNFK | F278: RULED | G278: 27000 | H278: ART | I278: 22DC | L278: OOG | M278: Full | N278: RULED | P278: =C278 | Q278: {=IFERROR(INDEX(Load_Booking_Report!AC:AC, MATCH(TRUE, ISNUMBER(FIND(SUBSTITUTE(C278," ",""), Load_Booking_Report!AL:AL)), 0)), "Not Found")} | R278: {=IFERROR(INDEX(Load_Booking_Report!C:C, MATCH(TRUE, ISNUMBER(FIND(SUBSTITUTE(C278," ",""), Load_Booking_Report!AL:AL)), 0)), "Not Found")} | S278: {=IFERROR(INDEX(Load_Booking_Report!AG:AG, MATCH(TRUE, ISNUMBER(FIND(SUBSTITUTE(C278," ",""), Load_Booking_Report!AL:AL)), 0)), "Not Found")} | T278: =G278 | U278: {=IFERROR( IF( INDEX(Load_Booking_Report!AM:AM, MATCH(TRUE, ISNUMBER(FIND(SUBSTITUTE(C278," ",""), Load_Booking_Report!AL:AL)), 0) )=0, "", INDEX(Load_Booking_Report!AM:AM, MATCH(TRUE, ISNUMBER(FIND(SUBSTITUTE(C278," ",""), Load_Booking_Report!AL:AL)), 0) ) ), "" )} | V278: {=IFERROR( IF( INDEX(Load_Booking_Report!AR:AR, MATCH(TRUE, ISNUMBER(FIND(SUBSTITUTE(C278," ",""), Load_Booking_Report!AL:AL)), 0) )=0, "", INDEX(Load_Booking_Report!AR:AR, MATCH(TRUE, ISNUMBER(FIND(SUBSTITUTE(C278," ",""), Load_Booking_Report!AL:AL)), 0) ) ), "" )} | W278: {=IFERROR(INDEX(Load_Booking_Report!F:F, MATCH(TRUE, ISNUMBER(FIND(SUBSTITUTE(C278," ",""), Load_Booking_Report!AL:AL)), 0)), "Not Found")} | X278: {=IFERROR(INDEX(Load_Booking_Report!N:N, MATCH(TRUE, ISNUMBER(FIND(SUBSTITUTE(C278," ",""), Load_Booking_Report!AL:AL)), 0)), "Not Found")} | Y278: {=IFERROR(INDEX(Load_Booking_Report!V:V, MATCH(TRUE, ISNUMBER(FIND(SUBSTITUTE(C278," ",""), Load_Booking_Report!AL:AL)), 0)), "Not Found")} | Z278: {=IFERROR(INDEX(Load_Booking_Report!BC:BC, MATCH(TRUE, ISNUMBER(FIND(SUBSTITUTE(C278," ",""), Load_Booking_Report!AL:AL)), 0)), "Not Found")}
A279: 23 | B279: 230104 | C279: ANON0000000 | D279: 20 | E279: USNFK | F279: RULED | G279: 23670 | H279: ART | I279: 22G1 | L279: 8'6 | M279: Full | N279: RULED | P279: =C279 | Q279: {=IFERROR(INDEX(Load_Booking_Report!AC:AC, MATCH(TRUE, ISNUMBER(FIND(SUBSTITUTE(C279," ",""), Load_Booking_Report!AL:AL)), 0)), "Not Found")} | R279: {=IFERROR(INDEX(Load_Booking_Report!C:C, MATCH(TRUE, ISNUMBER(FIND(SUBSTITUTE(C279," ",""), Load_Booking_Report!AL:AL)), 0)), "Not Found")} | S279: {=IFERROR(INDEX(Load_Booking_Report!AG:AG, MATCH(TRUE, ISNUMBER(FIND(SUBSTITUTE(C279," ",""), Load_Booking_Report!AL:AL)), 0)), "Not Found")} | T279: =G279 | U279: {=IFERROR( IF( INDEX(Load_Booking_Report!AM:AM, MATCH(TRUE, ISNUMBER(FIND(SUBSTITUTE(C279," ",""), Load_Booking_Report!AL:AL)), 0) )=0, "", INDEX(Load_Booking_Report!AM:AM, MATCH(TRUE, ISNUMBER(FIND(SUBSTITUTE(C279," ",""), Load_Booking_Report!AL:AL)), 0) ) ), "" )} | V279: {=IFERROR( IF( INDEX(Load_Booking_Report!AR:AR, MATCH(TRUE, ISNUMBER(FIND(SUBSTITUTE(C279," ",""), Load_Booking_Report!AL:AL)), 0) )=0, "", INDEX(Load_Booking_Report!AR:AR, MATCH(TRUE, ISNUMBER(FIND(SUBSTITUTE(C279," ",""), Load_Booking_Report!AL:AL)), 0) ) ), "" )} | W279: {=IFERROR(INDEX(Load_Booking_Report!F:F, MATCH(TRUE, ISNUMBER(FIND(SUBSTITUTE(C279," ",""), Load_Booking_Report!AL:AL)), 0)), "Not Found")} | X279: {=IFERROR(INDEX(Load_Booking_Report!N:N, MATCH(TRUE, ISNUMBER(FIND(SUBSTITUTE(C279," ",""), Load_Booking_Report!AL:AL)), 0)), "Not Found")} | Y279: {=IFERROR(INDEX(Load_Booking_Report!V:V, MATCH(TRUE, ISNUMBER(FIND(SUBSTITUTE(C279," ",""), Load_Booking_Report!AL:AL)), 0)), "Not Found")} | Z279: {=IFERROR(INDEX(Load_Booking_Report!BC:BC, MATCH(TRUE, ISNUMBER(FIND(SUBSTITUTE(C279," ",""), Load_Booking_Report!AL:AL)), 0)), "Not Found")}
A280: 23 | B280: 230402 | C280: ANON0000000 | D280: 20 | E280: USNFK | F280: RULED | G280: 23180 | H280: ART | I280: 22G1 | L280: 8'6 | M280: Full | N280: RULED | P280: =C280 | Q280: {=IFERROR(INDEX(Load_Booking_Report!AC:AC, MATCH(TRUE, ISNUMBER(FIND(SUBSTITUTE(C280," ",""), Load_Booking_Report!AL:AL)), 0)), "Not Found")} | R280: {=IFERROR(INDEX(Load_Booking_Report!C:C, MATCH(TRUE, ISNUMBER(FIND(SUBSTITUTE(C280," ",""), Load_Booking_Report!AL:AL)), 0)), "Not Found")} | S280: {=IFERROR(INDEX(Load_Booking_Report!AG:AG, MATCH(TRUE, ISNUMBER(FIND(SUBSTITUTE(C280," ",""), Load_Booking_Report!AL:AL)), 0)), "Not Found")} | T280: =G280 | U280: {=IFERROR( IF( INDEX(Load_Booking_Report!AM:AM, MATCH(TRUE, ISNUMBER(FIND(SUBSTITUTE(C280," ",""), Load_Booking_Report!AL:AL)), 0) )=0, "", INDEX(Load_Booking_Report!AM:AM, MATCH(TRUE, ISNUMBER(FIND(SUBSTITUTE(C280," ",""), Load_Booking_Report!AL:AL)), 0) ) ), "" )} | V280: {=IFERROR( IF( INDEX(Load_Booking_Report!AR:AR, MATCH(TRUE, ISNUMBER(FIND(SUBSTITUTE(C280," ",""), Load_Booking_Report!AL:AL)), 0) )=0, "", INDEX(Load_Booking_Report!AR:AR, MATCH(TRUE, ISNUMBER(FIND(SUBSTITUTE(C280," ",""), Load_Booking_Report!AL:AL)), 0) ) ), "" )} | W280: {=IFERROR(INDEX(Load_Booking_Report!F:F, MATCH(TRUE, ISNUMBER(FIND(SUBSTITUTE(C280," ",""), Load_Booking_Report!AL:AL)), 0)), "Not Found")} | X280: {=IFERROR(INDEX(Load_Booking_Report!N:N, MATCH(TRUE, ISNUMBER(FIND(SUBSTITUTE(C280," ",""), Load_Booking_Report!AL:AL)), 0)), "Not Found")} | Y280: {=IFERROR(INDEX(Load_Booking_Report!V:V, MATCH(TRUE, ISNUMBER(FIND(SUBSTITUTE(C280," ",""), Load_Booking_Report!AL:AL)), 0)), "Not Found")} | Z280: {=IFERROR(INDEX(Load_Booking_Report!BC:BC, MATCH(TRUE, ISNUMBER(FIND(SUBSTITUTE(C280," ",""), Load_Booking_Report!AL:AL)), 0)), "Not Found")}
